---------------------------------------
Begin Slurm Prolog: Sep-13-2024 23:21:24
Job ID:    1283370
User ID:   mghanem8
Account:   gts-agarg35
Job name:  SlurmPythonExample
Partition: gpu-rtx6000
QOS:       embers
---------------------------------------

The following have been reloaded with a version change:
  1) anaconda3/2022.05 => anaconda3/2022.05.0.1

/usr/local/pace-apps/lmod/lmod/init/bash: line 169: conda: command not found
Running the following command:
python train.py --config-name=train_diffusion_unet_ddim_hybrid_workspace.yaml task=orbit_needle_multi hydra.run.dir=/storage/home/hcoda1/7/mghanem8/codes/quest_v0/experiments/diffpolicy/orbit_needle_multi_50 training.seed=0 training.device=cuda:0 exp_name=orbit_needle_multi_50_multi-cam logging.mode=online task.dataset.max_train_episodes=50

============= Initialized Observation Utils with Obs Spec =============

using obs modality: low_dim with keys: ['joint_pos']
using obs modality: rgb with keys: ['image', 'wrist_image']
using obs modality: depth with keys: []
using obs modality: scan with keys: []
/storage/home/hcoda1/7/mghanem8/.conda/envs/robodiff/lib/python3.9/site-packages/torchvision/models/_utils.py:208: UserWarning: The parameter 'pretrained' is deprecated since 0.13 and will be removed in 0.15, please use 'weights' instead.
  warnings.warn(
/storage/home/hcoda1/7/mghanem8/.conda/envs/robodiff/lib/python3.9/site-packages/torchvision/models/_utils.py:223: UserWarning: Arguments other than a weight enum or `None` for 'weights' are deprecated since 0.13 and will be removed in 0.15. The current behavior is equivalent to passing `weights=None`.
  warnings.warn(msg)
[2024-09-13 23:25:19,804][diffusion_policy.model.diffusion.conditional_unet1d][INFO] - number of parameters: 2.555439e+08
Diffusion params: 2.555439e+08
Vision params: 2.290221e+07
Traceback (most recent call last):
  File "/storage/home/hcoda1/7/mghanem8/.conda/envs/robodiff/lib/python3.9/site-packages/wandb/sdk/wandb_init.py", line 1073, in init
    wi.setup(kwargs)
  File "/storage/home/hcoda1/7/mghanem8/.conda/envs/robodiff/lib/python3.9/site-packages/wandb/sdk/wandb_init.py", line 165, in setup
    self._wl = wandb_setup.setup()
  File "/storage/home/hcoda1/7/mghanem8/.conda/envs/robodiff/lib/python3.9/site-packages/wandb/sdk/wandb_setup.py", line 312, in setup
    ret = _setup(settings=settings)
  File "/storage/home/hcoda1/7/mghanem8/.conda/envs/robodiff/lib/python3.9/site-packages/wandb/sdk/wandb_setup.py", line 307, in _setup
    wl = _WandbSetup(settings=settings)
  File "/storage/home/hcoda1/7/mghanem8/.conda/envs/robodiff/lib/python3.9/site-packages/wandb/sdk/wandb_setup.py", line 293, in __init__
    _WandbSetup._instance = _WandbSetup__WandbSetup(settings=settings, pid=pid)
  File "/storage/home/hcoda1/7/mghanem8/.conda/envs/robodiff/lib/python3.9/site-packages/wandb/sdk/wandb_setup.py", line 106, in __init__
    self._setup()
  File "/storage/home/hcoda1/7/mghanem8/.conda/envs/robodiff/lib/python3.9/site-packages/wandb/sdk/wandb_setup.py", line 234, in _setup
    self._setup_manager()
  File "/storage/home/hcoda1/7/mghanem8/.conda/envs/robodiff/lib/python3.9/site-packages/wandb/sdk/wandb_setup.py", line 265, in _setup_manager
    self._manager = wandb_manager._Manager(
  File "/storage/home/hcoda1/7/mghanem8/.conda/envs/robodiff/lib/python3.9/site-packages/wandb/sdk/wandb_manager.py", line 108, in __init__
    self._service.start()
  File "/storage/home/hcoda1/7/mghanem8/.conda/envs/robodiff/lib/python3.9/site-packages/wandb/sdk/service/service.py", line 112, in start
    self._launch_server()
  File "/storage/home/hcoda1/7/mghanem8/.conda/envs/robodiff/lib/python3.9/site-packages/wandb/sdk/service/service.py", line 108, in _launch_server
    assert ports_found
AssertionError
wandb: ERROR Abnormal program exit
Error executing job with overrides: ['task=orbit_needle_multi', 'training.seed=0', 'training.device=cuda:0', 'exp_name=orbit_needle_multi_50_multi-cam', 'logging.mode=online', 'task.dataset.max_train_episodes=50']
Traceback (most recent call last):
  File "/storage/home/hcoda1/7/mghanem8/.conda/envs/robodiff/lib/python3.9/site-packages/wandb/sdk/wandb_init.py", line 1073, in init
    wi.setup(kwargs)
  File "/storage/home/hcoda1/7/mghanem8/.conda/envs/robodiff/lib/python3.9/site-packages/wandb/sdk/wandb_init.py", line 165, in setup
    self._wl = wandb_setup.setup()
  File "/storage/home/hcoda1/7/mghanem8/.conda/envs/robodiff/lib/python3.9/site-packages/wandb/sdk/wandb_setup.py", line 312, in setup
    ret = _setup(settings=settings)
  File "/storage/home/hcoda1/7/mghanem8/.conda/envs/robodiff/lib/python3.9/site-packages/wandb/sdk/wandb_setup.py", line 307, in _setup
    wl = _WandbSetup(settings=settings)
  File "/storage/home/hcoda1/7/mghanem8/.conda/envs/robodiff/lib/python3.9/site-packages/wandb/sdk/wandb_setup.py", line 293, in __init__
    _WandbSetup._instance = _WandbSetup__WandbSetup(settings=settings, pid=pid)
  File "/storage/home/hcoda1/7/mghanem8/.conda/envs/robodiff/lib/python3.9/site-packages/wandb/sdk/wandb_setup.py", line 106, in __init__
    self._setup()
  File "/storage/home/hcoda1/7/mghanem8/.conda/envs/robodiff/lib/python3.9/site-packages/wandb/sdk/wandb_setup.py", line 234, in _setup
    self._setup_manager()
  File "/storage/home/hcoda1/7/mghanem8/.conda/envs/robodiff/lib/python3.9/site-packages/wandb/sdk/wandb_setup.py", line 265, in _setup_manager
    self._manager = wandb_manager._Manager(
  File "/storage/home/hcoda1/7/mghanem8/.conda/envs/robodiff/lib/python3.9/site-packages/wandb/sdk/wandb_manager.py", line 108, in __init__
    self._service.start()
  File "/storage/home/hcoda1/7/mghanem8/.conda/envs/robodiff/lib/python3.9/site-packages/wandb/sdk/service/service.py", line 112, in start
    self._launch_server()
  File "/storage/home/hcoda1/7/mghanem8/.conda/envs/robodiff/lib/python3.9/site-packages/wandb/sdk/service/service.py", line 108, in _launch_server
    assert ports_found
AssertionError

The above exception was the direct cause of the following exception:

Traceback (most recent call last):
  File "/storage/home/hcoda1/7/mghanem8/codes/diffusion_policy/train.py", line 34, in <module>
    main()
  File "/storage/home/hcoda1/7/mghanem8/.conda/envs/robodiff/lib/python3.9/site-packages/hydra/main.py", line 90, in decorated_main
    _run_hydra(
  File "/storage/home/hcoda1/7/mghanem8/.conda/envs/robodiff/lib/python3.9/site-packages/hydra/_internal/utils.py", line 389, in _run_hydra
    _run_app(
  File "/storage/home/hcoda1/7/mghanem8/.conda/envs/robodiff/lib/python3.9/site-packages/hydra/_internal/utils.py", line 452, in _run_app
    run_and_report(
  File "/storage/home/hcoda1/7/mghanem8/.conda/envs/robodiff/lib/python3.9/site-packages/hydra/_internal/utils.py", line 216, in run_and_report
    raise ex
  File "/storage/home/hcoda1/7/mghanem8/.conda/envs/robodiff/lib/python3.9/site-packages/hydra/_internal/utils.py", line 213, in run_and_report
    return func()
  File "/storage/home/hcoda1/7/mghanem8/.conda/envs/robodiff/lib/python3.9/site-packages/hydra/_internal/utils.py", line 453, in <lambda>
    lambda: hydra.run(
  File "/storage/home/hcoda1/7/mghanem8/.conda/envs/robodiff/lib/python3.9/site-packages/hydra/_internal/hydra.py", line 132, in run
    _ = ret.return_value
  File "/storage/home/hcoda1/7/mghanem8/.conda/envs/robodiff/lib/python3.9/site-packages/hydra/core/utils.py", line 260, in return_value
    raise self._return_value
  File "/storage/home/hcoda1/7/mghanem8/.conda/envs/robodiff/lib/python3.9/site-packages/hydra/core/utils.py", line 186, in run_job
    ret.return_value = task_function(task_cfg)
  File "/storage/home/hcoda1/7/mghanem8/codes/diffusion_policy/train.py", line 31, in main
    workspace.run()
  File "/storage/home/hcoda1/7/mghanem8/codes/diffusion_policy/diffusion_policy/workspace/train_diffusion_unet_hybrid_workspace.py", line 115, in run
    wandb_run = wandb.init(
  File "/storage/home/hcoda1/7/mghanem8/.conda/envs/robodiff/lib/python3.9/site-packages/wandb/sdk/wandb_init.py", line 1114, in init
    raise Exception("problem") from error_seen
Exception: problem
srun: error: atl1-1-03-003-21-0: task 0: Exited with exit code 1
